Workbook

Sheet Özet
A1: BKA TUS · Farmakoloji — kart düzeltmeleri (önce / sonra)
A2: Kapsamdaki notların tamamı tek tek incelendi. Düzeltilen her not, değişikliğin en yüksek kritiklik düzeyine göre sıralanarak 'Değişiklikler' sayfasında önce/sonra biçiminde listelenir; tek tek düzeltmeler 'Değişiklik Kalemleri' sayfasındadır.
A4: Kapsam
A5: Kapsamdaki toplam not | B5: 669
A6: Önce/sonra listesindeki not | B6: =COUNTA('Değişiklikler'!N:N)-1 -> 667
A7: Yalnızca görünmez HTML temizliği yapılan not | B7: 1
A8: Değişiklik gerekmeyen not | B8: =B5-B6-B7 -> 1
A9: Toplam düzeltme kalemi | B9: =COUNTA('Değişiklik Kalemleri'!H:H)-1 -> 1766
A11: Kritiklik düzeyine göre not sayısı
A12: Düzey | B12: Not | C12: Pay | D12: Tanım
A13: Kritik | B13: =COUNTIF('Değişiklikler'!$B:$B,A13) -> 38 | C13: =IF($B$17=0,0,B13/$B$17) -> 0.056971514 | D13: Kart düzeltilmeden çalışılırsa yanlış bilgi öğretir; ya da güncelliğini yitirmiş, uygulanırsa zarar verebilecek bilgi içerir; ya da kart yapısal olarak bozuktur.
A14: Yüksek | B14: =COUNTIF('Değişiklikler'!$B:$B,A14) -> 174 | C14: =IF($B$17=0,0,B14/$B$17) -> 0.26086957 | D14: Anlamı değiştiren eksik niteleyici, sayısı tutmayan liste, ne sorulduğu belirsiz kök, yanlış okunabilecek kısaltma veya doğrulanması gereken şüpheli bilgi.
A15: Orta | B15: =COUNTIF('Değişiklikler'!$B:$B,A15) -> 374 | C15: =IF($B$17=0,0,B15/$B$17) -> 0.56071964 | D15: Anlamı değiştirmeyen terim/ilaç/eponim yazım hataları, kişisel kısaltmaların açılması, terminoloji güncellemesi ve dil bilgisi düzeltmeleri.
A16: Düşük | B16: =COUNTIF('Değişiklikler'!$B:$B,A16) -> 81 | C16: =IF($B$17=0,0,B16/$B$17) -> 0.12143928 | D16: Büyük/küçük harf, noktalama, ok ve ayraç standardı, boşluk ve gereksiz HTML temizliği.
A17: Toplam | B17: =SUM(B13:B16) -> 667 | C17: =SUM(C13:C16) -> 1
A19: Ders ve kritiklik dağılımı (not sayısı)
A20: Ders | B20: Kritik | C20: Yüksek | D20: Orta | E20: Düşük | F20: Toplam
A21: Farmakoloji | B21: =COUNTIFS('Değişiklikler'!$C:$C,$A21,'Değişiklikler'!$B:$B,B$20) -> 38 | C21: =COUNTIFS('Değişiklikler'!$C:$C,$A21,'Değişiklikler'!$B:$B,C$20) -> 174 | D21: =COUNTIFS('Değişiklikler'!$C:$C,$A21,'Değişiklikler'!$B:$B,D$20) -> 374 | E21: =COUNTIFS('Değişiklikler'!$C:$C,$A21,'Değişiklikler'!$B:$B,E$20) -> 81 | F21: =SUM(B21:E21) -> 667
A22: Toplam | B22: =SUM(B21:B21) -> 38 | C22: =SUM(C21:C21) -> 174 | D22: =SUM(D21:D21) -> 374 | E22: =SUM(E21:E21) -> 81 | F22: =SUM(F21:F21) -> 667
A24: Kategoriye göre düzeltme kalemi
A25: Kategori | B25: Kritik | C25: Yüksek | D25: Orta | E25: Düşük | F25: Toplam
A26: Tıbbi doğruluk | B26: =COUNTIFS('Değişiklik Kalemleri'!$C:$C,$A26,'Değişiklik Kalemleri'!$B:$B,B$25) -> 28 | C26: =COUNTIFS('Değişiklik Kalemleri'!$C:$C,$A26,'Değişiklik Kalemleri'!$B:$B,C$25) -> 53 | D26: =COUNTIFS('Değişiklik Kalemleri'!$C:$C,$A26,'Değişiklik Kalemleri'!$B:$B,D$25) -> 0 | E26: =COUNTIFS('Değişiklik Kalemleri'!$C:$C,$A26,'Değişiklik Kalemleri'!$B:$B,E$25) -> 0 | F26: =SUM(B26:E26) -> 81
A27: Güncellik | B27: =COUNTIFS('Değişiklik Kalemleri'!$C:$C,$A27,'Değişiklik Kalemleri'!$B:$B,B$25) -> 10 | C27: =COUNTIFS('Değişiklik Kalemleri'!$C:$C,$A27,'Değişiklik Kalemleri'!$B:$B,C$25) -> 51 | D27: =COUNTIFS('Değişiklik Kalemleri'!$C:$C,$A27,'Değişiklik Kalemleri'!$B:$B,D$25) -> 3 | E27: =COUNTIFS('Değişiklik Kalemleri'!$C:$C,$A27,'Değişiklik Kalemleri'!$B:$B,E$25) -> 0 | F27: =SUM(B27:E27) -> 64
A28: Eksik kritik bilgi | B28: =COUNTIFS('Değişiklik Kalemleri'!$C:$C,$A28,'Değişiklik Kalemleri'!$B:$B,B$25) -> 0 | C28: =COUNTIFS('Değişiklik Kalemleri'!$C:$C,$A28,'Değişiklik Kalemleri'!$B:$B,C$25) -> 64 | D28: =COUNTIFS('Değişiklik Kalemleri'!$C:$C,$A28,'Değişiklik Kalemleri'!$B:$B,D$25) -> 0 | E28: =COUNTIFS('Değişiklik Kalemleri'!$C:$C,$A28,'Değişiklik Kalemleri'!$B:$B,E$25) -> 0 | F28: =SUM(B28:E28) -> 64
A29: Soru netliği | B29: =COUNTIFS('Değişiklik Kalemleri'!$C:$C,$A29,'Değişiklik Kalemleri'!$B:$B,B$25) -> 0 | C29: =COUNTIFS('Değişiklik Kalemleri'!$C:$C,$A29,'Değişiklik Kalemleri'!$B:$B,C$25) -> 13 | D29: =COUNTIFS('Değişiklik Kalemleri'!$C:$C,$A29,'Değişiklik Kalemleri'!$B:$B,D$25) -> 41 | E29: =COUNTIFS('Değişiklik Kalemleri'!$C:$C,$A29,'Değişiklik Kalemleri'!$B:$B,E$25) -> 0 | F29: =SUM(B29:E29) -> 54
A30: Doğrulama gerekli | B30: =COUNTIFS('Değişiklik Kalemleri'!$C:$C,$A30,'Değişiklik Kalemleri'!$B:$B,B$25) -> 0 | C30: =COUNTIFS('Değişiklik Kalemleri'!$C:$C,$A30,'Değişiklik Kalemleri'!$B:$B,C$25) -> 0 | D30: =COUNTIFS('Değişiklik Kalemleri'!$C:$C,$A30,'Değişiklik Kalemleri'!$B:$B,D$25) -> 0 | E30: =COUNTIFS('Değişiklik Kalemleri'!$C:$C,$A30,'Değişiklik Kalemleri'!$B:$B,E$25) -> 0 | F30: =SUM(B30:E30) -> 0
A31: Yapısal | B31: =COUNTIFS('Değişiklik Kalemleri'!$C:$C,$A31,'Değişiklik Kalemleri'!$B:$B,B$25) -> 0 | C31: =COUNTIFS('Değişiklik Kalemleri'!$C:$C,$A31,'Değişiklik Kalemleri'!$B:$B,C$25) -> 14 | D31: =COUNTIFS('Değişiklik Kalemleri'!$C:$C,$A31,'Değişiklik Kalemleri'!$B:$B,D$25) -> 0 | E31: =COUNTIFS('Değişiklik Kalemleri'!$C:$C,$A31,'Değişiklik Kalemleri'!$B:$B,E$25) -> 0 | F31: =SUM(B31:E31) -> 14
A32: Terim/yazım | B32: =COUNTIFS('Değişiklik Kalemleri'!$C:$C,$A32,'Değişiklik Kalemleri'!$B:$B,B$25) -> 0 | C32: =COUNTIFS('Değişiklik Kalemleri'!$C:$C,$A32,'Değişiklik Kalemleri'!$B:$B,C$25) -> 1 | D32: =COUNTIFS('Değişiklik Kalemleri'!$C:$C,$A32,'Değişiklik Kalemleri'!$B:$B,D$25) -> 226 | E32: =COUNTIFS('Değişiklik Kalemleri'!$C:$C,$A32,'Değişiklik Kalemleri'!$B:$B,E$25) -> 50 | F32: =SUM(B32:E32) -> 277
A33: Kısaltma | B33: =COUNTIFS('Değişiklik Kalemleri'!$C:$C,$A33,'Değişiklik Kalemleri'!$B:$B,B$25) -> 0 | C33: =COUNTIFS('Değişiklik Kalemleri'!$C:$C,$A33,'Değişiklik Kalemleri'!$B:$B,C$25) -> 6 | D33: =COUNTIFS('Değişiklik Kalemleri'!$C:$C,$A33,'Değişiklik Kalemleri'!$B:$B,D$25) -> 486 | E33: =COUNTIFS('Değişiklik Kalemleri'!$C:$C,$A33,'Değişiklik Kalemleri'!$B:$B,E$25) -> 0 | F33: =SUM(B33:E33) -> 492
A34: Dil bilgisi | B34: =COUNTIFS('Değişiklik Kalemleri'!$C:$C,$A34,'Değişiklik Kalemleri'!$B:$B,B$25) -> 0 | C34: =COUNTIFS('Değişiklik Kalemleri'!$C:$C,$A34,'Değişiklik Kalemleri'!$B:$B,C$25) -> 0 | D34: =COUNTIFS('Değişiklik Kalemleri'!$C:$C,$A34,'Değişiklik Kalemleri'!$B:$B,D$25) -> 4 | E34: =COUNTIFS('Değişiklik Kalemleri'!$C:$C,$A34,'Değişiklik Kalemleri'!$B:$B,E$25) -> 68 | F34: =SUM(B34:E34) -> 72
A35: Biçim | B35: =COUNTIFS('Değişiklik Kalemleri'!$C:$C,$A35,'Değişiklik Kalemleri'!$B:$B,B$25) -> 0 | C35: =COUNTIFS('Değişiklik Kalemleri'!$C:$C,$A35,'Değişiklik Kalemleri'!$B:$B,C$25) -> 0 | D35: =COUNTIFS('Değişiklik Kalemleri'!$C:$C,$A35,'Değişiklik Kalemleri'!$B:$B,D$25) -> 0 | E35: =COUNTIFS('Değişiklik Kalemleri'!$C:$C,$A35,'Değişiklik Kalemleri'!$B:$B,E$25) -> 644 | F35: =SUM(B35:E35) -> 644
A36: Toplam | B36: =SUM(B26:B35) -> 38 | C36: =SUM(C26:C35) -> 202 | D36: =SUM(D26:D35) -> 760 | E36: =SUM(E26:E35) -> 762 | F36: =SUM(F26:F35) -> 1762
A38: Nasıl okunur
A39: • Önce sütunu özgün içeriği, Sonra sütunu güncel kart alanlarını gösterir. Önceki değişikliklerin renkli gösterimi korunmuştur; son yayın takibinde ilgili Sonra hücreleri tam güncel metinle yenilenmiştir.
A40: • {{c1::…}} işaretleri kartın boşluk doldurma (cloze) alanlarıdır. Hiçbir notta cloze numarası eklenmedi veya silinmedi; bu nedenle kart kimlikleri ve kullanıcıların çalışma geçmişi korunur. Cevap sızıntısını gidermek için bir satırın başka karta taşındığı notlar 'Yapısal' kalemi olarak ayrıca belirtilmiştir.
A41: • Görseller, renkler ve kodlamalar (akrostişler) korunmuştur; hiçbir not silinmedi, yeni not eklenmedi.
A42: • 'AI notu (ne · neden · nasıl)' sütunu her not için neyin değiştiğini, nedenini ve nasıl yapıldığını (kural kodlarıyla) anlatır. 'AI Rehberi' sayfası, bu çalışma kitabının başka derslerin kartları düzeltilirken şablon olarak nasıl kullanılacağını açıklar.
A43: • 'Karar' sütunu editörün kararına ayrılmıştır. Mevcut revizyonlar ve 09.10.2026 son yayın odak düzeltmeleri katalog paketine aktarılmıştır; boş karar hücresi tek başına tıbbi onay veya açık hata sayılmaz.
A44: • Kısaltmaların nasıl ele alındığı 'Kısaltma Sözlüğü' sayfasındadır. Aynı terim her kartta tek biçimde yazılır; seçilen yazımlar 'Yazım Birliği' sayfasındadır.
A45: • 'Sorulacaklar (Önce - Sonra)' sayfası: Kullanıcı / editör teyidi ve kararı gerektiren tüm maddeler (Farmakoloji'de 37 madde, Pediatri'de 40, Genel Cerrahi'de 27, Dahiliye'de 20, Kadın Doğum'da 17 ve Küçük Stajlar'da 14 madde olmak üzere toplam 155 madde) önce/sonra karşılaştırması, kırmızı çizili/yeşil kalın fark vurguları, klinik gerekçesi, editör tavsiyesi ve karar sütunuyla bu sayfada derlenmiştir.

Sheet Sorulacaklar (Önce - Sonra)
A1: Sıra | B1: Kritiklik | C1: Ders | D1: Konu | E1: Sorulacak Konu / Tıbbi Çelişki | F1: Önce | G1: Sonra (Önerilen / Mevcut) | H1: Tıbbi Gerekçe ve Sorulma Nedeni | I1: Önerilen Karar / Editör Tavsiyesi | J1: Kullanıcı Kararı | K1: Kullanıcı Notu | L1: Not ID
A2: 1 | B2: Kritik | C2: Farmakoloji | D2: Antimikrobiyal İlaçlar | E2: İNH hepatotoksisitesi: Klasik TUS asetilhidrazin kuralı vs güncel NAT2 genotip kanıtı | F2: Metin Metin INH Hızlı Asetilleyen --> {{c1::Toksik met artar ---> Hepatit}} Yavaş Asetilleyen --> {{c1::İNH artar --> B6 azalır ---> Per. Nöropati }} Ek bilgi (arka yüz) — Ek bilgi (arka yüz) — | G2: Metin İzoniazid (İNH) ve NAT2 asetilleyici fenotipi: Hızlı asetilleyen → İNH klirensi {{c1::daha yüksek}} Yavaş asetilleyen → İNH maruziyeti {{c1::daha yüksek}}; hepatotoksisite riski {{c1::daha yüksek bulunmuştur}} İNH ile B6 azalması → {{c1::periferik nöropati}} riski Ek bilgi (arka yüz) Hızlı asetilleyen → hepatit eşlemesi, eski asetilhidrazin metabolit şemasıdır; güncel klinik risk sınıflaması olarak kullanılmaz. NAT2 yavaş asetilleyici fenotipi çalışmalarda daha yüksek hepatotoksisite riskiyle ilişkilidir; risk ilaç rejimi ve diğer hasta özelliklerinden de etkilenir. | H2: Klinik hepatotoksisite riskini ters öğreten eski metabolit eşlemesi, NAT2 maruziyet/risk ilişkisiyle değiştirildi. Kaynak: https://pubmed.ncbi.nlm.nih.gov/39727196/ https://pubmed.ncbi.nlm.nih.gov/3691615/ | I2: 09.10.2026: bu odak düzeltmesi pakete uygulandı. Diğer iddialara toplu tıbbi onay verilmedi. | L2: 1604660471791
A3: 2 | B3: Kritik | C3: Farmakoloji | D3: Antineoplastik İlaçlar | E3: İrinotekan hücre siklusu faz spesifitesi: S fazı spesifik ilaçtır | F3: KT - Etki Ettiği Hc Siklus Dönemleri: G1: {{c3::L-Asp }} G1-S: {{c3::Etoposid}} G2-M: {{c1::Bleomisin}} - {{c1::İrinotekan}} M: {{c2::Vinkristin}} - {{c2::Vinblastin}} - {{c4::Paklitaksel}} - {{c4::Dosetaksel}} - Eribulin - İksabepilon | G3: Metin Kemoterapi ilaçlarının etki ettiği hücre siklusu dönemleri: G1: {{c3::L-asparaginaz}} S/G2: {{c3::etoposid}} S: {{c1::irinotekan}} G2-M: {{c1::bleomisin}} M: {{c2::vinkristin}}, {{c2::vinblastin}}, {{c4::paklitaksel}}, {{c4::dosetaksel}}, eribulin, iksabepilon Ek bilgi (arka yüz) İrinotekan S fazına özgüdür; etoposid başlıca S ve G2 fazlarında etkilidir. İlaçların faz ağırlıkları tek bir geçiş noktasında etkili oldukları anlamına gelmez. | H3: İrinotekan yanlış G2–M satırından S fazına taşındı; aynı tabloda etoposidin G1–S eşlemesi S/G2 olarak düzeltildi. c1–c4 ve diğer ilaçlar korundu. Kaynak: https://www.cancer.gov/publications/dictionaries/cancer-drug/def/irinotecan-hydrochloride https://www.cancer.gov/publications/dictionaries/cancer-drug/def/etoposide https://pubmed.ncbi.nlm.nih.gov/7947097/ | I3: 09.10.2026: bu odak düzeltmesi pakete uygulandı. Diğer iddialara toplu tıbbi onay verilmedi. | L3: 1624188510902
A4: 3 | B4: Kritik | C4: Farmakoloji | D4: Dermatolojik / İnflamatuvar İlaçlar | E4: Krisaborol vs Apremilast: Atopik dermatitte topikal PDE4 inhibitörü | F4: Atopik Dermatit TDV PDE4 inh (IL -23 baskılar) --> {{c1::Apremilast}} IL-4 / 13 baskılayan ---> {{c1::Dupilumab}} | G4: Hafif-orta atopik dermatit tedavisinde topikal olarak kullanılan fosfodiesteraz-4 (PDE4) inhibitörü: {{c1::Krisaborol}} (Apremilast ise psöriyazis ve psöriyatik artritte oral kullanılan PDE4 inhibitörüdür). | H4: Krisaborol, atopik dermatit tedavisinde kullanılan topikal bir PDE4 (fosfodiesteraz-4) inhibitörüdür. Apremilast ise psöriyazis ve psöriyatik artritte oral yoldan kullanılan bir PDE4 inhibitörüdür. Kartta atopik dermatitte oral ajanlarla ve IL-23 ile karışıklık mevcuttur. | I4: Krisaborolün 'atopik dermatit tedavisinde kullanılan topikal PDE4 inhibitörü' olduğu netleştirilmeli, oral apremilasttan ayrılmalıdır. | L4: 1604757853167
A5: 4 | B5: Kritik | C5: Farmakoloji | D5: Endokrin ve Metabolizma İlaçları | E5: GLP-1 agonistleri kontrendikasyonları (GFR < 30 kısıtlaması) | F5: Metin Metin GLP-1 Agonistleri KEND {{c1::GFR}} < 30 {{c1::Tiroit Medüller}} Ca Ek bilgi (arka yüz) — Ek bilgi (arka yüz) — | G5: Metin GLP-1 agonistlerinin kontrendikasyonları: {{c1::GFR < 30 mL/dk}} (özellikle eksenatid) {{c1::Medüller tiroit}} kanseri (kişisel veya ailesel öykü), MEN2 Ek bilgi (arka yüz) Liraglutid, dulaglutid ve semaglutidde böbrek yetmezliğinde doz ayarı gerekmez; eski kaynaklarda GFR < 30 mL/dk tüm grup için kontrendikasyon olarak genellenmiştir. | H5: Eski TUS spotlarında tüm GLP-1 agonistleri için GFR < 30 kontrendike olarak verilir; ancak bu kısıtlama özellikle eksenatid için geçerlidir. Liraglutid, dulaglutid ve semaglutidde böbrek yetmezliğinde doz ayarı gerekmez. Medüller tiroit kanseri (kişisel/ailesel öykü) ve MEN2 ise mutlak kontrendikasyondur. | I5: GFR < 30 kısıtlamasının eksenatide özgü olduğu ve medüller tiroit kanseri / MEN2 kontrendikasyonu netleştirilmelidir. | L5: 1604680392251
A6: 5 | B6: Kritik | C6: Farmakoloji | D6: Genel Farmakoloji ve Toksikoloji | E6: Tamoksifen ve Klopidogrel metabolizması: CYP2D6 vs CYP2C19 ayrımı | F6: Metin {{c1::CYP2C19}} ---> Tamoksifen ve Klopidogrel Hızlı çalışırsa ---> etkinlikleri {{c1::ARTAR}} Ek bilgi (arka yüz) İkisi de ön ilaç | G6: Metin Ön ilaç aktivasyonu: Tamoksifen: N-desmetiltamoksifen → endoksifen dönüşümündeki temel enzim {{c1::CYP2D6}}. Klopidogrel: aktif metabolit oluşumunda başlıca enzim {{c1::CYP2C19}}; bu enzimin işlevi azaldığında antiplatelet etki {{c1::azalır}}. Ek bilgi (arka yüz) Tamoksifen metabolizmasına CYP2C19 dahil birden çok enzim katılır; endoksifen oluşumunda CYP2D6 temel rol oynar. Enzim aktivitesinden her iki ilaç için koşulsuz klinik etkinlik artışı çıkarılamaz. Tamoksifende metabolit düzeyi ile klinik sonlanım aynı ölçüt değildir. | H6: Ortak CYP2C19 ve kesin etkinlik artışı cevabı yerine iki ilacın aktivasyon enzimleri ayrıldı; farmakokinetik ilişki klinik etkinlikle karıştırılmadı. Kaynak: https://dailymed.nlm.nih.gov/dailymed/drugInfo.cfm?setid=1e6ff055-590c-41e6-9530-1fdf04cdbd02 https://dailymed.nlm.nih.gov/dailymed/lookup.cfm?setid=de8b0b67-eb25-4684-83b5-7ad785314227 | I6: 09.10.2026: bu odak düzeltmesi pakete uygulandı. Diğer iddialara toplu tıbbi onay verilmedi. | L6: 1604660192048
A7: 6 | B7: Kritik | C7: Farmakoloji | D7: Santral Sinir Sistemi İlaçları | E7: Pargilin selektivitesi: MAO-B selektif değil, non-selektif irreversibl MAO inhibitörüdür | F7: Metin MAO İnh'leri: Non-Selektif İnh: {{c1::Tranilsipromin}} - {{c1::Pargilin}} - {{c2::İsokarboksazid}} - {{c2::Fenelzin}} MAO-A İnh: {{c3::Moklobemid}} - Brofaramin - Pirlindol MAO-B İnh: {{c3::Selejilin}} - {{c3::Rasajilin}} Ek bilgi (arka yüz) MAO-B önemli | G7: Selektif MAO-B inhibitörleri: İrreversibl: {{c1::Selegilin}}, {{c1::rasajilin}} Reversibl: {{c1::Safinamid}} (Pargilin non-selektif MAO inhibitörüdür). | H7: Pargilin klasik olarak non-selektif irreversibl bir MAO inhibitörüdür (eski antihipertansif). MAO-B selektif irreversibl inhibitör selegilin ve rasajilindir; safinamid ise reversibl MAO-B inhibitörüdür. Pargilinin MAO-B selektif olarak kodlanması tıbbi hatadır. | I7: Pargilin MAO-B listesinden çıkarılmalı veya non-selektif MAO inhibitörleri arasına alınmalıdır; MAO-B selektif olarak selegilin ve rasajilin korunmalıdır. | L7: 1624171626287
A8: 7 | B8: Kritik | C8: Dahiliye | D8: Genel | E8: "Serum karoten: normal" ve "D-ksiloz: normal" satırları içerik değiştirilmeden işaretlendi | F8: Metin İBBAÇ: Serum Karoten ölçümü: {{c1::NORMAL}} D-Xyloz: {{c1::NORMAL}} Ek bilgi (arka yüz) ÇÜNKÜ: İntestinal Yüzeyin EMİLİM Fonk'u NORMAL | G8: Metin İnce bağırsakta bakteriyel aşırı çoğalma: Serum karoten ölçümü: {{c1::normal}} D-ksiloz: {{c1::normal}} Ek bilgi (arka yüz) Çünkü: İntestinal yüzeyin emilim fonksiyonu normaldir | H8: Bakteriyel aşırı çoğalmada safra asitlerinin dekonjugasyonu yağ ve yağda eriyen madde emilimini bozar; bu nedenle serum karotenin düşük bulunması beklenir. Merck kaynağına göre bakteriler pentozu metabolize ettiği için D-ksiloz testi de anormal çıkabilir. Kartın iki "normal" cevabı bu bilgiyle çelişiyor; dayanılan TUS kaynağı ve Harrison malabsorpsiyon tablosuyla karşılaştırılmalı. | I8: İBBAÇ'ta (SIBO) yağ malabsorpsiyonuna bağlı serum karoten düşer; D-ksiloz testi de bozulabilir. Harrison doğrultusunda kök/cevap netleştirilmelidir. | L8: 1619721875288
A9: 8 | B9: Kritik | C9: Genel Cerrahi | D9: Genel | E9: Barrett özofagusunun laparoskopik RYGB için göreceli kontrendikasyon olduğu bilgisi içerik değiştirilmeden işaretlendi | F9: Laparos. Roux en Y göreceli KEND'ları --> {{c1::DEA}} - {{c1::Barret}} Özo | G9: Laparoskopik Roux-en-Y gastrik bypassın göreceli kontrendikasyonları → {{c1::demir eksikliği anemisi}}, {{c1::Barrett}} özofagusu | H9: Güncel bariatrik literatürde Barrett özofagusu sleeve gastrektomi için göreceli kontrendikasyondur; RYGB ise reflüyü azalttığı için Barrett'lı obez hastada tercih edilen ameliyattır ve çalışmalarda hastaların önemli bir kısmında RYGB sonrası Barrett'ın gerilediği bildirilir. Kartın Barrett'ı RYGB kontrendikasyonu sayan kaynağı doğrulanamadı; sleeve gastrektomiyle karıştırılmış olabilir. | I9: RYGB reflüyü azalttığı için Barrett'ta tercih edilen yöntemdir; sleeve gastrektomi rölatif kontrendikedir. İki cerrahinin yer değiştirmesi önerilir. | L9: 1605467478120
A10: 9 | B10: Kritik | C10: Kadın Doğum | D10: Genel | E10: "15 hafta sonra β-hCG yüksekse kemoterapi" ifadesi içerik değiştirilmeden işaretlendi | F10: Molde, uterusun boşaltılmasından {{c1::15}} hafta sonra bhCG yüksekse hâlâ --> {{c1::KT}} verilir | G10: Molar gebelikte uterusun boşaltılmasından {{c1::15}} hafta sonra β-hCG hâlâ yüksekse {{c1::kemoterapi}} verilir | H10: FIGO'nun postmolar gestasyonel trofoblastik neoplazi tanı ölçütleri bir hafta eşiği içermez: en az 3 hafta boyunca 4 ölçümde plato, en az 2 hafta boyunca 3 ardışık ölçümde artış veya histolojik koryokarsinom. Eski ölçütlerdeki "boşaltımdan 6 ay sonra saptanabilir hCG" ölçütü de güncel FIGO raporunda kaldırılmış, düşmekte olan hCG'nin izlenebileceği belirtilmiştir. Taranan kaynaklarda 15. haftada hâlâ yüksek hCG'nin tek başına kemoterapi endikasyonu olduğu bulunamadı; kart gereksiz kemoterapi öğretebilir. Eşik yazarın kaynağından doğrulanmalı. | I10: FIGO postmolar GTN kriterlerinde 15. hafta kuralı yer almaz (plato veya yükselme aranır). Güncel FIGO kriterleri eklenmelidir. | L10: 1608553896302
A11: 10 | B11: Yüksek | C11: Farmakoloji | D11: Antimikrobiyal İlaçlar | E11: Ön ilaç antibiyotikler listesi: İzoniazid eksikliği | F11: Metin Ön İlaç ABler (3) --> {{c1::Metronidazol - Kloramfenikol - Pirazinamid }} Ek bilgi (arka yüz) — | G11: Ön ilaç (prodrug) yapısındaki klasik antimikrobiyal ilaçlar: 1) Mikobakteriyel KatG enzimiyle aktive olan: {{c1::İzoniazid (İNH)}} 2) Parenteral form için süksinat tuzu kullanılan: {{c1::Kloramfenikol süksinat}} 3) Proguanil (aktif şekli: sikloguanil) | H11: Kloramfenikol süksinat veya palmitat suda çözünürlüğü ve tadı ayarlamak için kullanılan ön ilaç formlarıdır. Ancak antimikrobiyal farmakolojisinde en klasik ön ilaç mikobakteriyel KatG enzimiyle aktive olan izoniaziddir (İNH). Kartta izoniazidin bulunmaması eksikliktir. | I11: Ön ilaç antibiyotikler listesine bakteriyel KatG katalaz-peroksidaz enzimiyle aktif formuna dönüşen İzoniazid (İNH) eklenmelidir. | L11: 1604751532610
A12: 11 | B12: Yüksek | C12: Farmakoloji | D12: Antimikrobiyal İlaçlar | E12: Flukloksasilin ve Abakavir: HLA-B*5701 aşırı duyarlılık cloze maskelemesi | F12: HLA - Toks Abakavir Deri Toks: HLA B{{c1::57:01}} Allopürinol Deri Tok: HLA B{{c1::58:01}} KMP Deri Toks: HLA B{{c2::15:02}} Amok Klav KC Toks: HLA DRB1-5 DQB1 Fluoksasilin KC Toks: HLA {{c2::B*57:01}} | G12: HLA-B*5701 ile ilişkili advers ilaç reaksiyonları: 1) Ağır sistemik hipersensitivite sendromu: {{c1::Abakavir}} 2) İlaca bağlı kolestatik karaciğer hasarı: {{c1::Flukloksasilin}} | H12: HLA-B*5701 alleli ile ilişkili iki klasik ilaç abakavir (ağır hipersensitivite) ve flukloksasilindir (kolestatik hepatit). Özgün kartta flukloksasilin ve abakavir farklı cloze numaralarında maskelenirken birbirinin cevabını sızdırmaktaydı. | I12: Her iki ilacın klinik tablosu (Abakavir: sistemik hipersensitivite; Flukloksasilin: ilaca bağlı kolestatik karaciğer hasarı) ayrı satırlarda netleştirilerek maskelenmelidir. | L12: 1621973964873
A13: 12 | B13: Yüksek | C13: Farmakoloji | D13: Antimikrobiyal İlaçlar | E13: Klorokin dirençli P. falciparum profilaksisi: Başlıktaki cloze maskesi soruyu gizliyor | F13: Klorokin Dirençli P. falc Pfx: {{c1::Meflokin}} {{c1::Doks}} {{c1::Atovokon + Proguanil}} Akut Vivax Atağında Oral kullanılan ama EkzoEritrositer formları eradike etmeyen ilaç: {{c1::Klorokin}} | G13: Klorokin dirençli P. falciparum profilaksisinde kullanılan ilaçlar: 1) {{c1::Meflokin}} 2) {{c1::Atovakuon + proguanil}} 3) {{c1::Doksisiklin}} | H13: Özgün kartta kökte {{c1::Klorokin}} maskelenmiş olduğundan, soru ilk açıldığında hangi ilaca karşı dirençli sıtma profilaksisinin sorulduğu anlaşılamamakta, gereksiz kafa karışıklığı yaratmaktadır. İlaç direnci başlıkta açıkça belirtilmeli, asıl sorulan profilaksi ilaçları (Meflokin, Atovakuon-proguanil, Doksisiklin) maskelenmelidir. | I13: Başlıktaki cloze maskesi kaldırılmalı ('Klorokin dirençli P. falciparum profilaksisi:'), cevap seçenekleri maskelenerek soru netleştirilmelidir. | L13: 1626519693103
... A156: 155 | B156: Orta | C156: Farmakoloji | D156: Santral Sinir Sistemi İlaçları | E156: Ön ilaç benzodiazepinler: 'Tek ilaç klorazepat' ifadesi | F156: BDZ'lerden alındığı anda inaktif olan tek ilaç --> {{c1::Klorozapat}} | G156: Midede hidroliz ve dekarboksilasyonla aktif metaboliti desmetildiazepama (nordazepam) dönüşen ön ilaç benzodiazepin: {{c1::Klorazepat}} (Prazepam da benzer şekilde ön ilaç yapısındadır). | H156: Klorazepat midede dekarboksillenerek nordazepam'a (desmetildiazepam) dönüşen bir ön ilaçtır. Ancak prazepam da aktif metabolitine dönüşen bir ön ilaçtır. 'Tek ön ilaç klorazepattır' ifadesi mutlaklaştırıcıdır. | I156: 'Ön ilaç benzodiazepin örneği: Klorazepat (ve prazepam)' şeklinde düzeltilmelidir. | L156: 1604732974650

Sheet AI Rehberi
A1: AI Rehberi — kart düzeltme şablonu
A2: Bu çalışma kitabı, bir öğrencinin kendi çalışması için tuttuğu TUS kartlarının (Anki notları) profesyonel, herkesin anlayacağı ve TUS ile uyumlu kartlara nasıl dönüştürüldüğünü baştan sona gösteren bir örnektir. Başka bir dersin kartlarını düzeltecek yapay zekâ modeli bu sayfayı sözleşme; 'Değişiklikler' sayfasındaki Önce, Sonra, Yapılan değişiklikler, Gerekçe ve AI notu sütunlarını ise çalışılmış örnek olarak kullanır.
A4: 1. Girdi ve çıktı
A5: • Girdi: Anki notları. Boşluk doldurma (cloze) notlarında 'Metin' ve 'Ek bilgi (arka yüz)', klasik notlarda 'Soru' ve 'Cevap' alanı vardır. Alanlar ham HTML'dir; {{c1::…}} işaretinin her numarası ayrı bir karttır.
A6: • Çıktı: değişen her not için alanların tam yeni metni; kritiklik düzeyi ve kategorisiyle değişiklik kalemleri; Kritik ve Yüksek kalemler için gerekçe ve AI notu. Uygulanabilir düzeltmeler ayrıca .patch.json dosyasındadır.
A7: • Değişiklikler, editör 'Karar' sütununda Kabul seçmeden pakete uygulanmaz.
A9: 2. Önerilen iş akışı
A10: 1. Düzenleme: her not tek tek okunur ve öncelik sırasına göre düzeltilir; her değişiklik bir kalem olarak kaydedilir.
A11: 2. Tıbbi doğrulama: Kritik ve Yüksek düzeyli her değişiklik, düzenleyiciden bağımsız ikinci bir gözle kaynaklara karşı kontrol edilir.
A12: 3. Yazım birliği: kart metinleri, kalemler ve gerekçeler yazım, dil bilgisi ve terim tutarlılığı için okunur; ders genelinde tek yazım tablosu uygulanır ('Yazım Birliği' sayfası).
A13: 4. Son okuma: bütün kartlar güncel kaynaklarla yeniden okunur, kalan şüpheler araştırılarak kapatılır, kişisel not dili kaldırılır ve her nota AI notu yazılır.
A14: 5. Teslim: kritikliğe göre sıralı önce/sonra çalışma kitabı ve uygulanabilir düzeltme dosyası.
... A34: 5. Kritiklik düzeyleri
A35: Düzey | B35: Ne zaman kullanılır | C35: İzin verilen kategoriler
A36: Kritik | B36: Kart düzeltilmeden çalışılırsa yanlış bilgi öğretir; ya da güncelliğini yitirmiş, uygulanırsa zarar verebilecek bilgi içerir; ya da kart yapısal olarak bozuktur. | C36: Tıbbi doğruluk, Güncellik, Eksik kritik bilgi, Doğrulama gerekli, Yapısal
A37: Yüksek | B37: Anlamı değiştiren eksik niteleyici, sayısı tutmayan liste, ne sorulduğu belirsiz kök, yanlış okunabilecek kısaltma veya doğrulanması gereken şüpheli bilgi. | C37: Tıbbi doğruluk, Güncellik, Eksik kritik bilgi, Soru netliği, Doğrulama gerekli, Yapısal, Terim/yazım, Kısaltma
A38: Orta | B38: Anlamı değiştirmeyen terim/ilaç/eponim yazım hataları, kişisel kısaltmaların açılması, terminoloji güncellemesi ve dil bilgisi düzeltmeleri. | C38: Güncellik, Soru netliği, Yapısal, Terim/yazım, Kısaltma, Dil bilgisi
A39: Düşük | B39: Büyük/küçük harf, noktalama, ok ve ayraç standardı, boşluk ve gereksiz HTML temizliği. | C39: Yapısal, Terim/yazım, Dil bilgisi, Biçim
A41: 6. Kural kodları (AI notlarının 'Nasıl' satırında kullanılır)
A42: Kod | B42: Kural | C42: Örnek satır ('Değişiklikler')
A43: YP1 | B43: Cloze numaraları sabit: numara eklenmez, silinmez, birleştirilmez; yalnız içerik düzeltilir | C43: Sıra 1 · Not ID 1626880744237
A44: YP2 | B44: Cevap sızıntısı giderilir | C44: Sıra 44 · Not ID 1626519693103
A45: YP3 | B45: Görsel, ses, renk ve kodlama (akrostiş) harfleri korunur | C45: Sıra 218 · Not ID 1604751290928
A46: YP4 | B46: Teknik temizlik: geçerli HTML, → oku, &nbsp; ve boş satır artıkları | C46: Sıra 452 · Not ID 1628885915273
A47: TD1 | B47: Yanlış tıbbi bilgi kaynağa dayanarak düzeltilir | C47: Sıra 1 · Not ID 1626880744237
A48: TD2 | B48: Klasik TUS bilgisi güncel kaynakla çelişirse TUS'un beklediği cevap "klasik" diye çerçevelenerek korunur ve güncel bilgi Extra'da verilir; klasik bilgi artık savunulmuyorsa güncel bilgi öğretilir, eski biçim Extra'da anılır | C48: Sıra 5 · Not ID 1604665702981
A49: TD3 | B49: Şüphe araştırıldı, bilgi doğru bulundu ve korundu | C49: Sıra 170 · Not ID 1604674704666
A50: GN1 | B50: Piyasadan çekilen, kısıtlanan veya onay almamış ilaç güncel seçenek gibi sunulmaz | C50: Sıra 2 · Not ID 1630501532743
A51: GN2 | B51: Güncel ad yazılır, TUS'ta kullanılan eski ad veya eponim korunur | C51: Sıra 262 · Not ID 1604664053617
A52: EK1 | B52: İfadeyi doğru kılan eksik niteleyici eklenir (doz, "en sık", "ilk tercih", "tek başına değil") | C52: Sıra 39 · Not ID 1604750468970
A53: EK2 | B53: Liste ve sayı tutarlılığı: sayı listeyle örtüşür, tanımlayıcı eksik üye eklenir | C53: Sıra 41 · Not ID 1604752207302
... A62: BÇ1 | B62: Biçim: büyük/küçük harf, liste ayracı, sayı ve birim yazımı | C62: Sıra 364 · Not ID 1604757145079
A64: 7. TUS uyumu ve kaynaklar
A65: • Kaynak sırası: (1) TUS sorularının dayandığı ders kitaplarının güncel baskıları (Katzung, Goodman & Gilman, Kayaalp, Lippincott, Rang & Dale); (2) düzenleyici kurum bilgileri (FDA, EMA, TİTCK); (3) güncel kılavuzlar; (4) tartışmalı mekanizmalar için NCBI Bookshelf ve PubMed. TUS hazırlık kitapları hangi sürümün beklendiğini gösterir; ilk üç kaynağı geçersiz kılmaz.
A66: • Kart, ÖSYM'nin doğru kabul edeceği bilgiyi öğretir ve tıbbi olarak yanlış bir şeyi gerçek gibi sunmaz. Klasik TUS bilgisi güncel kaynaklarla çelişiyorsa TUS'un beklediği cevap kartta "klasik bilgiye göre" gibi bir çerçeveyle korunur, güncel bilgi Ek bilgi alanında tek cümleyle verilir; klasik bilgiyi artık hiçbir ders kitabı savunmuyorsa kart güncel bilgiyi öğretir, eski biçim Ek bilgi alanında anılır (TD2). Ders kitapları arasında meşru bir fark varsa yazarın TUS sürümü korunur.
A67: • Emin olunamayan bilgi değiştirilmez: önce araştırılır; araştırmayla çözülemezse 'Doğrulama gerekli' kalemiyle işaretlenir.
A68: • Piyasadan çekilen ilaç karttan silinmez, çünkü TUS hâlâ sorabilir; çekilme yılı karta eklenir (GN1).
A69: • Kaynak uydurulmaz: yalnız gerçekten okunan sayfa veya kesin bilinen ders kitabı anılır; sayfa numarası, baskı, URL veya çalışma uydurulmaz.
A71: 8. Profesyonel kart ölçütleri
A72: • Kart tek başına anlaşılır: yazarın notlarını hiç görmemiş bir TUS adayı ne sorulduğunu bilir; kök ilacı, sınıfı veya konuyu ve sorulan özelliği adlandırır.
...

Sheet Değişiklikler
A1: Sıra | B1: Kritiklik | C1: Ders | D1: Konu | E1: Önce | F1: Sonra | G1: Yapılan değişiklikler | H1: Gerekçe (Kritik/Yüksek) | I1: AI notu (ne · neden · nasıl) | J1: Karar | K1: Editör notu | L1: Not tipi | M1: Değişen alan | N1: Not ID
A2: 1 | B2: Kritik | C2: Farmakoloji | D2: Antineoplastik İlaçlar | E2: KardiyoTxk olmayan Antrasiklin: {{c1::Daktinomisin}} | F2: DNA'ya interkale olan, kardiyotoksik olmayan antitümör antibiyotik: {{c1::Daktinomisin}} | G2: • Kritik · Tıbbi doğruluk: "Kardiyotoksik olmayan antrasiklin" → "DNA'ya interkale olan, kardiyotoksik olmayan antitümör antibiyotik" • Orta · Kısaltma: KardiyoTxk → kardiyotoksik | H2: • Tıbbi doğruluk: Daktinomisin (aktinomisin D) antrasiklin değil, kromopeptid yapıda bir antitümör antibiyotiktir; antrasiklinler gibi DNA'ya (guanin-sitozin baz çiftleri arasına) interkale olur ancak kardiyotoksisite yapmaz (Katzung). Kart ilacı yanlış sınıfta öğretiyordu. | I2: Ne: Kökteki "kardiyotoksik olmayan antrasiklin" ifadesi "DNA'ya interkale olan, kardiyotoksik olmayan antitümör antibiyotik" yapıldı; cevap (daktinomisin) değişmedi. Neden: Daktinomisin antrasiklin değil, kromopeptid yapıda bir antitümör antibiyotiktir; eski kök ilacı yanlış sınıfta öğretiyordu. "KardiyoTxk" yazarın kişisel kısaltmasıydı. Nasıl: [TD1, YP1, KS1] Cevap doğru olduğu için korundu, yalnız kökteki yanlış sınıf adı doğru sınıfla değiştirildi ve cevabı ayırt ettiren iki özellik (DNA'ya interkalasyon, kardiyotoksisite yokluğu) kökte bırakıldı; c1 numarası aynı kaldı. Kaynak: Katzung, Basic & Clinical Pharmacology, antitümör antibiyotikler bölümü. | L2: Boşluk doldurma (cloze) | M2: Metin | N2: 1626880744237
A3: 2 | B3: Kritik | C3: Farmakoloji | D3: Antineoplastik İlaçlar | E3: Metin Hemato Zor ilaçlar Spleen Tirozin Kinaz İNH (ITP Tdv) --> {{c1::Fosfamatinib}} HBS polimerizasyon İNH (Orak Hc Anemi Tdv) --> {{c1::Vokselotor}} vWF Antikoru (TTP Tdv) --> {{c1::Kaplasizumab}} Ek bilgi (arka yüz) Kaplasizumab Önemli | F3: Metin Hematoloji ilaçları Dalak tirozin kinaz (SYK) inhibitörü (İTP tedavisi) → {{c1::fostamatinib}} HbS polimerizasyon inhibitörü (orak hücreli anemi tedavisi) → {{c1::vokselotor}} (2024'te piyasadan çekildi) vWF antikoru (TTP tedavisi) → {{c1::kaplasizumab}} Ek bilgi (arka yüz) — | G3: • Kritik · Güncellik: Vokselotora "(2024'te piyasadan çekildi)" eklendi • Orta · Terim/yazım: Fosfamatinib → fostamatinib; Spleen Tirozin Kinaz → Dalak tirozin kinaz (SYK); HBS → HbS • Orta · Kısaltma: İNH → inhibitörü; Tdv → tedavisi; Hc → hücreli • Düşük · Biçim: "Hemato Zor ilaçlar" → "Hematoloji ilaçları"; Extra'daki "Kaplasizumab Önemli" notu kaldırıldı; --> → →; büyük/küçük harf (kodlamadaki kalın "or" korundu); ITP → İTP | H3: • Güncellik: Pfizer, pazarlama sonrası çalışmalarda vazooklüzif kriz ve ölüm sayısındaki artış nedeniyle Eylül 2024'te vokselotoru (Oxbryta) tüm pazarlardan geri çekti; kart ilacı orak hücreli anemide güncel tedavi seçeneği gibi sunuyordu. | I3: Ne: "Hemato Zor ilaçlar" başlığı "Hematoloji ilaçları" yapıldı, kısaltmalar açıldı (İNH → inhibitörü, Tdv → tedavisi), "Fosfamatinib" → "fostamatinib" düzeltildi, vokselotora "(2024'te piyasadan çekildi)" eklendi ve Extra'daki "Kaplasizumab Önemli" notu kaldırıldı. Neden: Başlık ve Extra yazarın kendine aldığı notlardı; vokselotor Eylül 2024'te vazooklüzif kriz ve ölüm artışı nedeniyle tüm pazarlardan çekildiği hâlde kart onu güncel tedavi gibi sunuyordu. Nasıl: [GN1, SN2, KS1, YP3] Çekilen ilaç karttan silinmedi, çünkü TUS hâlâ sorabilir; çekilme bilgisi aynı satıra kalın olarak eklendi. Kodlamanın kalın "or" harfleri korundu, kişisel işaret taşıyan Extra boşaltıldı. Kaynak: Pfizer basın duyurusu (Eylül 2024) ve FDA güvenlik bildirimi (26 Eylül 2024). | L3: Boşluk doldurma (cloze) | M3: Metin + Ek bilgi (arka yüz) | N3: 1630501532743
A4: 3 | B4: Kritik | C4: Farmakoloji | D4: Endokrin ve Metabolizma İlaçları | E4: Metin Obezite Tdv. İlaçları {{c1::Orlistat}} - {{c2::Liraglutid}} - {{c3::Lorcaserin}} (5HT2C agonist)*** - {{c1::Naltrekson}} + {{c2::Bupropion}} - {{c3::Fentermin}} - {{c1::Topiramat}} Ek bilgi (arka yüz) — | F4: Metin Obezite tedavisinde kullanılan ilaçlar {{c1::Orlistat}}, {{c2::liraglutid}}, {{c3::lorkaserin}} (5-HT2C agonisti; 2020'de piyasadan çekildi), {{c1::naltrekson}} + {{c2::bupropion}}, {{c3::fentermin}} + {{c1::topiramat}} Ek bilgi (arka yüz) Güncel seçeneklere semaglutid (2,4 mg) ve tirzepatid de eklenmiştir. | G4: • Kritik · Güncellik: Lorkaserine "2020'de piyasadan çekildi" eklendi • Yüksek · Tıbbi doğruluk: "Fentermin - Topiramat" → "fentermin + topiramat" • Yüksek · Güncellik: Extra'ya semaglutid ve tirzepatid eklendi • Orta · Terim/yazım: Lorcaserin → lorkaserin; 5HT2C → 5-HT2C • Düşük · Biçim: Tdv. → tedavisinde; *** ve &nbsp; kaldırıldı; liste ayracı virgül | H4: • Güncellik: FDA, CAMELLIA-TIMI 61 çalışmasında kanser sıklığı artışı nedeniyle 2020'de lorkaserinin piyasadan çekilmesini istedi; kart ilacı güncel seçenek gibi sunuyordu. • Tıbbi doğruluk: Topiramat obezitede tek başına değil, fenterminle sabit doz kombinasyonu olarak onaylıdır. • Güncellik: Güncel obezite farmakoterapisinin en etkili iki ajanı listede yoktu. | I4: Ne: Başlık "Obezite tedavisinde kullanılan ilaçlar" yapıldı, "Lorcaserin" → "lorkaserin" yazılıp yanına kalın "(5-HT2C agonisti; 2020'de piyasadan çekildi)" eklendi ve "Fentermin - Topiramat" → "fentermin + topiramat" oldu. "***" kaldırıldı, Extra'ya semaglutid (2,4 mg) ile tirzepatid eklendi. Neden: Lorkaserin kanser artışı nedeniyle 2020'de çekildiği hâlde güncel seçenek gibi duruyordu; topiramat obezitede yalnız fenterminle sabit doz kombinasyonu olarak onaylıdır ve en etkili güncel iki ajan listede yoktu. Nasıl: [GN1, EK1, YP1] Çekilen ilaç TUS'ta sorulabildiği için silinmedi, durumu cloze dışına kalın yazıldı; kombinasyonlar "+" ile gösterildi ve c1, c2, c3 numaraları ile dağılımları korundu. Naltrekson + bupropion kombinasyonunun AB ruhsatının sürdüğü doğrulandı. Kaynak: FDA güvenlik bildirimi, 13 Şubat 2020 (lorkaserin, CAMELLIA-TIMI 61); EMA Mysimba EPAR sayfası (ruhsatlı). | L4: Boşluk doldurma (cloze) | M4: Metin + Ek bilgi (arka yüz) | N4: 1604736119248
A5: 4 | B5: Kritik | C5: Farmakoloji | D5: Genel | E5: {{c1::Amanitin}} --> mantar txn'i. 2 hf hiçbşi olmaz. sonra Fulminan KC yet | F5: {{c1::Amanitin}} → mantar toksini; ilk 6–24 saat belirti olmaz, ardından gastroenterit ve 3–5. günde fulminan karaciğer yetmezliği | G5: • Kritik · Tıbbi doğruluk: "2 hf hiçbşi olmaz. sonra Fulminan KC yet" → "ilk 6–24 saat belirti olmaz, ardından gastroenterit ve 3–5. günde fulminan karaciğer yetmezliği" • Orta · Kısaltma: txn → toksini; KC yet → karaciğer yetmezliği; hf (hafta) düzeltilen ifadede kaldırıldı • Düşük · Biçim: --> → →; &nbsp; temizlendi | H5: • Tıbbi doğruluk: Amatoksin zehirlenmesinde belirtisiz dönem 6–24 saattir; ardından şiddetli gastroenterit, yalancı iyileşme ve 3–5. günlerde fulminan karaciğer yetmezliği gelişir. Günler-haftalar süren belirtisiz dönem böbrek yetmezliği yapan orellanin (Cortinarius) zehirlenmesinin özelliğidir. | I5: Ne: "2 hf hiçbşi olmaz. sonra Fulminan KC yet" → "ilk 6–24 saat belirti olmaz, ardından gastroenterit ve 3–5. günde fulminan karaciğer yetmezliği" yapıldı; "txn" ve "KC yet" açıldı. Neden: Kart amatoksin zehirlenmesindeki belirtisiz dönemi iki hafta olarak öğretiyordu; bu dönem saatlerle ölçülür ve karaciğer yetmezliği ilk günler içinde gelişir. Nasıl: [TD1, KS1, YP1] Yanlış süre klinik seyrin üç evresiyle (latent dönem, gastroenterit, karaciğer evresi) değiştirildi; cevap ve c1 cloze'u korundu. Kaynak: Ann Emerg Med 1987, Kuzey Amerika mantar zehirlenmelerinin ayırıcı tanısı (amatoksinde 10–12 saatlik latent dönem); Clin Toxicol 2008 olgu sunumu (8. saatte gastroenterit, 3. günde karaciğer hasarı); Katzung, 13. baskı, zehirlenmiş hasta bölümü. | L5: Boşluk doldurma (cloze) | M5: Metin | N5: 1604664556223
A6: 5 | B6: Kritik | C6: Farmakoloji | D6: Genel | E6: Metin Modafinil --> Direkt etkili {{c1::alfa1}} agonist Ek bilgi (arka yüz) — | F6: Metin Modafinil → {{c1::dopamin ve noradrenalin geri alımını}} inhibe eder Ek bilgi (arka yüz) Eski kaynaklarda direkt etkili alfa-1 agonisti olarak geçer; etki mekanizması tam bilinmemektedir. | G6: • Kritik · Tıbbi doğruluk: "Direkt etkili alfa1 agonist" → "dopamin ve noradrenalin geri alımını inhibe eder"; Extra'ya eski tanım eklendi • Düşük · Biçim: --> → →; &nbsp; temizlendi | H6: • Tıbbi doğruluk: Katzung'a göre modafinilin etki mekanizması tam bilinmez; noradrenalin ve dopamin taşıyıcılarını inhibe eder. FDA etiketine göre dopamin taşıyıcısına bağlanır ve alfa-adrenerjik agonistlere yanıt veren in vitro sistemlerde etkisizdir; uyanıklık etkisinin prazosinle azalması doğrudan alfa-1 agonizmini göstermez. | I6: Ne: "Direkt etkili alfa1 agonist" → "dopamin ve noradrenalin geri alımını inhibe eder" yapıldı ve Extra'ya "Eski kaynaklarda direkt etkili alfa-1 agonisti olarak geçer; etki mekanizması tam bilinmemektedir." eklendi. Neden: Modafinil alfa-1 reseptörüne doğrudan bağlanmaz; uyanıklık etkisinin prazosinle azalması, dopamin geri alımının engellenmesine bağlı dolaylı adrenerjik uyarıyla açıklanır. Kart eski bir varsayımı kesin mekanizma gibi öğretiyordu. Nasıl: [TD2, TD1, YP1] Güncel ders kitabındaki mekanizma karta yazıldı, TUS'un eski soru kalıbını tanıtmak için eski tanım Extra'da tek cümleyle anıldı; tek c1 numarası korunup cevabın içeriği değiştirildi. Kaynak: Katzung, Basic & Clinical Pharmacology, 13. baskı, sempatomimetik ilaçlar bölümü; Provigil (modafinil) FDA etiketi, DailyMed, bölüm 12.1; "Modafinil as a Catecholaminergic Agent" derlemesi (PMC3791559). | L6: Boşluk doldurma (cloze) | M6: Metin + Ek bilgi (arka yüz) | N6: 1604665702981
A7: 6 | B7: Kritik | C7: Farmakoloji | D7: Genel | E7: Rezerpin {{c1::Uptake-1}} ile nörona girer {{c1::Uptake-1}} inh (TCA) --> Rezerpin akt {{c1::azalır }} | F7: Guanetidin {{c1::uptake-1}} ile nörona girer {{c1::Uptake-1}} inhibitörleri (trisiklik antidepresanlar) → guanetidin aktivitesi {{c1::azalır}} | G7: • Kritik · Tıbbi doğruluk: Rezerpin → Guanetidin (iki yerde) • Orta · Kısaltma: inh → inhibitörleri; TCA → trisiklik antidepresanlar; akt → aktivitesi • Düşük · Biçim: --> → →; büyük harfler; &nbsp; temizlendi | H7: • Tıbbi doğruluk: Uptake-1 (NET) ile adrenerjik sinir ucuna taşınan ve bu taşınma etkisi için zorunlu olduğundan trisiklik antidepresanlar ve kokainle etkisi azalan ilaç guanetidindir (Katzung). Rezerpin lipofilik olduğu için membranlardan kendiliğinden geçerek VMAT'ı inhibe eder, uptake-1'e bağımlı değildir; kart iki ilacı karıştırıyordu. | I7: Ne: Kartın öznesi "Rezerpin" → "Guanetidin" yapıldı (iki yerde); "inh (TCA)" → "inhibitörleri (trisiklik antidepresanlar)" ve "akt" → "aktivitesi" açıldı; uptake-1 ve "azalır" cevapları değişmedi. Neden: Etkisi için uptake-1 (NET) ile sinir ucuna girmesi zorunlu olan ve bu yüzden trisiklik antidepresanlarla etkisi azalan ilaç guanetidindir; rezerpin lipofiliktir ve VMAT'ı uptake-1'den bağımsız olarak inhibe eder. Nasıl: [TD1, KS1, YP1] Cevaplar (uptake-1, azalır) doğru olduğu için korundu, yalnız kökteki yanlış ilaç adı değiştirildi; böylece öğrencinin öğrendiği etkileşim doğru ilaca bağlandı ve c1 numarası aynı kaldı. Kaynak: Katzung, Basic & Clinical Pharmacology, 13. baskı, antihipertansif ilaçlar bölümü (guanetidin NET ile taşınır; kokain, amfetamin ve trisiklik antidepresanlar etkisini bloke eder). | L7: Boşluk doldurma (cloze) | M7: Metin | N7: 1604665993718
A8: 7 | B8: Kritik | C8: Farmakoloji | D8: Genel | E8: Metin Amilorid Kullanım END'ları --> {{c1::Li'a bağlı Nef. DI }} / {{c1::Kistik Fibrozis}} Ek bilgi (arka yüz) — | F8: Metin Amilorid kullanım endikasyonları → {{c1::lityuma bağlı nefrojenik diabetes insipidus}} / {{c1::Liddle sendromu}} Ek bilgi (arka yüz) Eski kaynaklarda kistik fibrozis de sayılır; inhale amiloridin kistik fibroziste yararı gösterilmemiştir. | G8: • Kritik · Tıbbi doğruluk: "Kistik Fibrozis" → "Liddle sendromu"; Extra'ya eski bilgi ve güncel kanıt eklendi • Orta · Kısaltma: END → endikasyonları; Li'a bağlı Nef. DI → lityuma bağlı nefrojenik diabetes insipidus • Düşük · Biçim: --> → →; büyük/küçük harf; &nbsp; temizlendi | H8: • Tıbbi doğruluk: Cochrane derlemesine (2014) göre inhale amilorid kistik fibroziste solunum durumunu iyileştirmez ve akciğer fonksiyonunda sınırlı kötüleşme kanıtı vardır; bu kullanım yerleşik bir endikasyon olmamıştır. Katzung'a göre amilorid, spironolaktonun etkisiz olduğu Liddle sendromunda yararlıdır. | I8: Ne: İkinci endikasyon "Kistik Fibrozis" → "Liddle sendromu" yapıldı, Extra'ya "Eski kaynaklarda kistik fibrozis de sayılır; inhale amiloridin kistik fibroziste yararı gösterilmemiştir." eklendi ve "Li'a bağlı Nef. DI" açıldı. Neden: İnhale amiloridin kistik fibrozis denemeleri yarar göstermemiştir ve bu kullanım yerleşik bir endikasyon olmamıştır; kart onu endikasyon gibi öğretiyordu. Ders kitabının saydığı ayırt edici endikasyon Liddle sendromudur. Nasıl: [TD2, TD1, EK2, YP1] İki üyeli liste yapısı ve c1 numarası korundu; yanlış üye, kaynağın aynı ilaç için verdiği tanımlayıcı endikasyonla değiştirildi ve eski bilgi Extra'da tek cümleyle anıldı. Kaynak: Katzung, Basic & Clinical Pharmacology, 13. baskı, diüretikler bölümü (lityuma bağlı poliüri ve Liddle sendromu); Cochrane Database of Systematic Reviews 2014, "Sodium channel blockers for cystic fibrosis". | L8: Boşluk doldurma (cloze) | M8: Metin + Ek bilgi (arka yüz) | N8: 1604668649061
A9: 8 | B9: Kritik | C9: Farmakoloji | D9: Genel | E9: Metin MetilDopa MoA {{c1::DOPA Dekarboksilaz inh }} Ek bilgi (arka yüz) — | F9: Metin Metildopanın etki mekanizması {{c1::Alfa-metilnoradrenaline dönüşür → santral alfa-2 agonisti}} Ek bilgi (arka yüz) Eski kaynaklarda DOPA dekarboksilaz inhibitörü olarak geçer; antihipertansif etkisi bu inhibisyona bağlı değildir. | G9: • Kritik · Tıbbi doğruluk: DOPA Dekarboksilaz inh → Alfa-metilnoradrenaline dönüşür → santral alfa-2 agonisti; Extra'ya eski tanım eklendi • Orta · Soru netliği: MetilDopa MoA → Metildopanın etki mekanizması • Düşük · Biçim: &nbsp; temizlendi | H9: • Tıbbi doğruluk: Metildopa DOPA dekarboksilaz ve dopamin beta-hidroksilazla sırasıyla alfa-metildopamine ve alfa-metilnoradrenaline dönüşür; antihipertansif etkisini alfa-metilnoradrenalinin beyin sapındaki alfa-2 reseptörlerini uyararak sempatik akışı azaltmasıyla gösterir (Katzung). DOPA dekarboksilazı zayıf inhibe etmesi etki mekanizması değildir; klinikte kullanılan DOPA dekarboksilaz inhibitörleri karbidopa ve benseraziddir. | I9: Ne: Cevap "DOPA Dekarboksilaz inh" → "Alfa-metilnoradrenaline dönüşür → santral alfa-2 agonisti" yapıldı, kök "MetilDopa MoA" → "Metildopanın etki mekanizması" oldu ve Extra'ya "Eski kaynaklarda DOPA dekarboksilaz inhibitörü olarak geçer; antihipertansif etkisi bu inhibisyona bağlı değildir." eklendi. Neden: Metildopanın antihipertansif etkisi, metaboliti alfa-metilnoradrenalinin santral alfa-2 reseptörlerini uyarmasından kaynaklanır; kart eski kaynaklardaki enzim inhibisyonu tanımını etki mekanizması gibi öğretiyordu. Nasıl: [TD2, TD1, SN1, YZ1] Güncel mekanizma c1 cevabına yazıldı; dönüşümde iki enzim rol aldığından cevapta enzim adı verilmedi, metabolitin adı kursun "noradrenalin" yazımına uyduruldu ve eski TUS kalıbı Extra'da tek cümleyle anıldı. Kaynak: Katzung, Basic & Clinical Pharmacology, 13. baskı, antihipertansif ilaçlar bölümü; Am J Psychiatry 1983, alfa-metildopa ve depresyon derlemesi (alfa-metildopanın DOPA dekarboksilaz inhibitörü olarak tanımlanması). | L9: Boşluk doldurma (cloze) | M9: Metin + Ek bilgi (arka yüz) | N9: 1604674111739
A10: 9 | B10: Kritik | C10: Farmakoloji | D10: Genel | E10: CxCR4 Antagonisti anemi tedavisinde kullanılan ilaç ---> {{c1::Preliksafor }} | F10: CXCR4 antagonisti, hematopoetik kök hücre mobilizasyonunda kullanılan ilaç → {{c1::pleriksafor}} | G10: • Kritik · Tıbbi doğruluk: "anemi tedavisinde kullanılan" → "hematopoetik kök hücre mobilizasyonunda kullanılan" • Orta · Terim/yazım: Preliksafor → pleriksafor; CxCR4 → CXCR4 • Düşük · Biçim: ---> → →; büyük/küçük harf; &nbsp; temizlendi | H10: • Tıbbi doğruluk: Pleriksafor CXCR4 antagonistidir; kök hücrelerin kemik iliğinden periferik kana geçişini sağlar ve non-Hodgkin lenfoma ile multipl miyelomda otolog nakil öncesi kök hücre toplamak için G-CSF ile birlikte kullanılır. Anemi tedavisinde endikasyonu yoktur. | I10: Ne: Kökteki "anemi tedavisinde kullanılan" → "hematopoetik kök hücre mobilizasyonunda kullanılan" düzeltildi; "Preliksafor" → "pleriksafor", "CxCR4" → "CXCR4" yazıldı. Neden: Pleriksaforun anemide endikasyonu yoktur; kart ilacın kullanım alanını yanlış öğretiyordu. İlaç adında harf yer değiştirmesi, reseptör simgesinde büyük/küçük harf hatası vardı. Nasıl: [TD1, YZ2, KS2] Cevap (pleriksafor) ve mekanizma (CXCR4 antagonizması) doğru olduğu için korundu, yalnız yanlış endikasyon prospektüsteki endikasyonla değiştirildi; yeni endikasyon ifadesi FDA prospektüsüyle doğrulandı. Kaynak: DailyMed, MOZOBIL (pleriksafor) prospektüsü: non-Hodgkin lenfoma ve multipl miyelomda otolog nakil için filgrastimle birlikte kök hücre mobilizasyonu. | L10: Boşluk doldurma (cloze) | M10: Metin | N10: 1604679231221
A11: 10 | B11: Kritik | C11: Farmakoloji | D11: Genel | E11: Metin L-DOPA mide asit salgısını {{c1::ARTIRIR }} Ek bilgi (arka yüz) Ülserli hastaya verme | F11: Metin L-DOPA, peptik ülser öyküsü olan hastada üst GİS kanaması riskini {{c1::artırır}} Ek bilgi (arka yüz) Peptik ülserde dikkatli kullanılır. | G11: • Kritik · Tıbbi doğruluk: "L-DOPA mide asit salgısını ARTIRIR" → "L-DOPA, peptik ülser öyküsü olan hastada üst GİS kanaması riskini artırır"; Extra "Ülserli hastaya verme" → "Peptik ülserde dikkatli kullanılır." • Düşük · Biçim: Cloze içindeki ARTIRIR → artırır; &nbsp; temizlendi | H11: • Tıbbi doğruluk: İnsanda L-DOPA tek başına uyarılmış mide asit salgısını azaltmış, karbidopayla birlikte değiştirmemiştir (Gut 1985); uzun süreli L-DOPA ve dekarboksilaz inhibitörü tedavisinde de asit salgısında değişiklik bulunmamıştır (Eur Neurol 1976). Ürün bilgileri ülserle ilişkili riski üst GİS kanaması olarak tanımlar ve peptik ülser öyküsünü kontrendikasyon değil, dikkat gerektiren durum sayar. | I11: Ne: "L-DOPA mide asit salgısını ARTIRIR" kökü "L-DOPA, peptik ülser öyküsü olan hastada üst GİS kanaması riskini artırır" yapıldı; Extra'daki "Ülserli hastaya verme" notu "Peptik ülserde dikkatli kullanılır." oldu. Neden: İnsan çalışmaları L-DOPA'nın mide asit salgısını artırmadığını gösterir; ürün bilgilerinde ülserle ilgili risk üst GİS kanamasıdır ve peptik ülser kontrendikasyon değil, dikkat gerektiren bir durumdur. Nasıl: [TD1, YP1, EK3] Cevap ("artırır") ve kartın ülser uyarısı korunarak yanlış mekanizma doğru risk ifadesiyle değiştirildi; c1 tek cloze olarak kaldı ve Extra güncel ürün bilgisine göre yazıldı. Aynı ilacın 1604735956639 numaralı kontrendikasyon kartıyla uyum sağlandı. Kaynak: Effect of L-dopa with and without inhibition of extra cerebral dopa decarboxylase on gastric acid secretion and gastrin release in man, Gut 1985 (PubMed 4054700); European Neurology 1976 (PubMed 1253804); Sinemet FDA prospektüsü ve Sinemet İngiltere KÜB (emc), uyarılar bölümleri. | L11: Boşluk doldurma (cloze) | M11: Metin + Ek bilgi (arka yüz) | N11: 1604735922068
A12: 11 | B12: Kritik | C12: Farmakoloji | D12: Genel | E12: Narkolepsi tdv'de kullanılan Hist 3-4 Res Blokörleri (2)----> {{c1::Pitolisant - Tiprolisant}} | F12: Narkolepsi tedavisinde kullanılan H3 reseptör blokörü → {{c1::pitolisant (eski adı tiprolisant)}} | G12: • Kritik · Tıbbi doğruluk: "(2) → Pitolisant - Tiprolisant" → "pitolisant (eski adı tiprolisant)"; sayı kaldırıldı • Yüksek · Tıbbi doğruluk: "Hist 3-4 Res Blokörleri" → "H3 reseptör blokörü" • Orta · Kısaltma: tdv'de → tedavisinde; Hist → H; Res → reseptör • Düşük · Biçim: ----> → →; büyük/küçük harf | H12: • Tıbbi doğruluk: Tiprolisant, pitolisantın (BF2.649) eski adıdır; aynı molekül iki ayrı ilaç gibi sayılıyordu. • Tıbbi doğruluk: Pitolisant seçici H3 reseptör antagonisti/ters agonistidir; H4 reseptörü üzerinden etkisi yoktur. | I12: Ne: "Hist 3-4 Res Blokörleri (2) → Pitolisant - Tiprolisant" → "H3 reseptör blokörü → pitolisant (eski adı tiprolisant)" yapıldı; sayı kaldırıldı ve "tdv'de" → "tedavisinde" açıldı. Neden: Tiprolisant pitolisantın eski adıdır, yani aynı molekül iki ayrı ilaç gibi sayılıyordu; pitolisant H3 reseptörünün antagonisti/ters agonistidir, H4 reseptörü üzerinden etkisi yoktur. Nasıl: [TD1, EK2, KS1] Cevap tek molekül olarak birleştirildi, öğrencinin eski kaynaklarda karşılaşabileceği ad parantezde korundu; iki ayrı ilaç varmış gibi gösteren sayı (2) kaldırıldı ve c1 numarası değişmedi. Kaynak: WAKIX (pitolisant) FDA etiketi, DailyMed (H3 reseptör antagonisti/ters agonisti; narkolepside gündüz aşırı uykululuğu ve katapleksi). | L12: Boşluk doldurma (cloze) | M12: Metin | N12: 1604747625714
A13: 12 | B13: Kritik | C13: Farmakoloji | D13: Genel | E13: RA tdv'de kullanılan Rekomb CTLA - 4 (2)--> {{c1::Abatacept - Belatacept }} | F13: Rekombinant CTLA-4 füzyon proteinleri (2) → {{c1::abatasept (RA), belatasept (böbrek nakli)}} | G13: • Kritik · Tıbbi doğruluk: "RA tdv'de kullanılan" kök ifadesi kaldırıldı; endikasyonlar cevaba eklendi: abatasept (RA), belatasept (böbrek nakli) • Orta · Terim/yazım: Abatacept → abatasept; Belatacept → belatasept • Orta · Kısaltma: Rekomb → rekombinant • Düşük · Biçim: --> → →; liste ayracı virgül; "CTLA - 4" → "CTLA-4"; kalın yazı içindeki boşluk kaldırıldı; &nbsp; temizlendi | H13: • Tıbbi doğruluk: Belatasept RA'da değil, böbrek naklinde rejeksiyon profilaksisinde onaylıdır; RA'da kullanılan CTLA-4-Ig füzyon proteini abatasepttir. | I13: Ne: "RA tdv'de kullanılan" kökü kaldırıldı ve endikasyonlar cevaba eklendi: "abatasept (RA), belatasept (böbrek nakli)"; "Abatacept/Belatacept" → "abatasept/belatasept", "Rekomb" → "rekombinant" yazıldı. Neden: Belatasept RA'da değil, böbrek naklinde organ rejeksiyonu profilaksisinde onaylıdır; eski kök iki ilacı da RA ilacı gibi öğretiyordu. Nasıl: [TD1, YZ2, KS1] Kök iki ilacın ortak özelliğine (rekombinant CTLA-4 füzyon proteini) daraltıldı ve ayırt edici endikasyonlar cevabın içine alındı; yazarın abatasepti kalın yazması, sayı (2) ve c1 numarası korundu. Kaynak: NULOJIX (belatasept) FDA etiketi, DailyMed (böbrek nakli alıcılarında organ rejeksiyonu profilaksisi; CTLA-4 füzyon proteini). | L13: Boşluk doldurma (cloze) | M13: Metin | N13: 1604749989489
... A668: 667 | B668: Düşük | C668: Farmakoloji | D668: Solunum ve Sindirim Sistemi İlaçları | E668: Bronkoselektif antimuskarinik --> {{c1::İpratropium}} Mukosilier Klirensi {{c1::etkilemez}} | F668: Bronkoselektif antimuskarinik → {{c1::ipratropium}} Mukosilier klirensi {{c1::etkilemez}} | G668: • Düşük · Biçim: --> → →; büyük/küçük harf; &nbsp; temizlendi | H668: — | I668: Ne: "-->" oku "→" yapıldı, "İpratropium" ve "Mukosilier Klirensi" küçük harfe çevrildi, &nbsp; temizlendi. Neden: Bilgi doğruydu (ipratropium atropinden farklı olarak mukosilier klirensi baskılamaz); yalnız ok ve büyük harf kullanımı ev stiline uymuyordu. Nasıl: [BÇ1, YP4] Yalnız biçim düzeltildi; ipratropium inhale kuaterner antimuskarinik ilaçların prototipi olduğundan cevap ve iki c1 cloze'u korundu. | L668: Boşluk doldurma (cloze) | M668: Metin | N668: 1608631333779

Sheet Değişiklik Kalemleri
A1: Sıra | B1: Kritiklik | C1: Kategori | D1: Ders | E1: Konu | F1: Değişiklik | G1: Gerekçe | H1: Not ID
A2: 1 | B2: Kritik | C2: Tıbbi doğruluk | D2: Farmakoloji | E2: Antineoplastik İlaçlar | F2: "Kardiyotoksik olmayan antrasiklin" → "DNA'ya interkale olan, kardiyotoksik olmayan antitümör antibiyotik" | G2: Daktinomisin (aktinomisin D) antrasiklin değil, kromopeptid yapıda bir antitümör antibiyotiktir; antrasiklinler gibi DNA'ya (guanin-sitozin baz çiftleri arasına) interkale olur ancak kardiyotoksisite yapmaz (Katzung). Kart ilacı yanlış sınıfta öğretiyordu. | H2: 1626880744237
A3: 4 | B3: Kritik | C3: Tıbbi doğruluk | D3: Farmakoloji | E3: Genel | F3: "2 hf hiçbşi olmaz. sonra Fulminan KC yet" → "ilk 6–24 saat belirti olmaz, ardından gastroenterit ve 3–5. günde fulminan karaciğer yetmezliği" | G3: Amatoksin zehirlenmesinde belirtisiz dönem 6–24 saattir; ardından şiddetli gastroenterit, yalancı iyileşme ve 3–5. günlerde fulminan karaciğer yetmezliği gelişir. Günler-haftalar süren belirtisiz dönem böbrek yetmezliği yapan orellanin (Cortinarius) zehirlenmesinin özelliğidir. | H3: 1604664556223
A4: 5 | B4: Kritik | C4: Tıbbi doğruluk | D4: Farmakoloji | E4: Genel | F4: "Direkt etkili alfa1 agonist" → "dopamin ve noradrenalin geri alımını inhibe eder"; Extra'ya eski tanım eklendi | G4: Katzung'a göre modafinilin etki mekanizması tam bilinmez; noradrenalin ve dopamin taşıyıcılarını inhibe eder. FDA etiketine göre dopamin taşıyıcısına bağlanır ve alfa-adrenerjik agonistlere yanıt veren in vitro sistemlerde etkisizdir; uyanıklık etkisinin prazosinle azalması doğrudan alfa-1 agonizmini göstermez. | H4: 1604665702981
A5: 6 | B5: Kritik | C5: Tıbbi doğruluk | D5: Farmakoloji | E5: Genel | F5: Rezerpin → Guanetidin (iki yerde) | G5: Uptake-1 (NET) ile adrenerjik sinir ucuna taşınan ve bu taşınma etkisi için zorunlu olduğundan trisiklik antidepresanlar ve kokainle etkisi azalan ilaç guanetidindir (Katzung). Rezerpin lipofilik olduğu için membranlardan kendiliğinden geçerek VMAT'ı inhibe eder, uptake-1'e bağımlı değildir; kart iki ilacı karıştırıyordu. | H5: 1604665993718
A6: 7 | B6: Kritik | C6: Tıbbi doğruluk | D6: Farmakoloji | E6: Genel | F6: "Kistik Fibrozis" → "Liddle sendromu"; Extra'ya eski bilgi ve güncel kanıt eklendi | G6: Cochrane derlemesine (2014) göre inhale amilorid kistik fibroziste solunum durumunu iyileştirmez ve akciğer fonksiyonunda sınırlı kötüleşme kanıtı vardır; bu kullanım yerleşik bir endikasyon olmamıştır. Katzung'a göre amilorid, spironolaktonun etkisiz olduğu Liddle sendromunda yararlıdır. | H6: 1604668649061
A7: 8 | B7: Kritik | C7: Tıbbi doğruluk | D7: Farmakoloji | E7: Genel | F7: DOPA Dekarboksilaz inh → Alfa-metilnoradrenaline dönüşür → santral alfa-2 agonisti; Extra'ya eski tanım eklendi | G7: Metildopa DOPA dekarboksilaz ve dopamin beta-hidroksilazla sırasıyla alfa-metildopamine ve alfa-metilnoradrenaline dönüşür; antihipertansif etkisini alfa-metilnoradrenalinin beyin sapındaki alfa-2 reseptörlerini uyararak sempatik akışı azaltmasıyla gösterir (Katzung). DOPA dekarboksilazı zayıf inhibe etmesi etki mekanizması değildir; klinikte kullanılan DOPA dekarboksilaz inhibitörleri karbidopa ve benseraziddir. | H7: 1604674111739
A8: 9 | B8: Kritik | C8: Tıbbi doğruluk | D8: Farmakoloji | E8: Genel | F8: "anemi tedavisinde kullanılan" → "hematopoetik kök hücre mobilizasyonunda kullanılan" | G8: Pleriksafor CXCR4 antagonistidir; kök hücrelerin kemik iliğinden periferik kana geçişini sağlar ve non-Hodgkin lenfoma ile multipl miyelomda otolog nakil öncesi kök hücre toplamak için G-CSF ile birlikte kullanılır. Anemi tedavisinde endikasyonu yoktur. | H8: 1604679231221
A9: 10 | B9: Kritik | C9: Tıbbi doğruluk | D9: Farmakoloji | E9: Genel | F9: "L-DOPA mide asit salgısını ARTIRIR" → "L-DOPA, peptik ülser öyküsü olan hastada üst GİS kanaması riskini artırır"; Extra "Ülserli hastaya verme" → "Peptik ülserde dikkatli kullanılır." | G9: İnsanda L-DOPA tek başına uyarılmış mide asit salgısını azaltmış, karbidopayla birlikte değiştirmemiştir (Gut 1985); uzun süreli L-DOPA ve dekarboksilaz inhibitörü tedavisinde de asit salgısında değişiklik bulunmamıştır (Eur Neurol 1976). Ürün bilgileri ülserle ilişkili riski üst GİS kanaması olarak tanımlar ve peptik ülser öyküsünü kontrendikasyon değil, dikkat gerektiren durum sayar. | H9: 1604735922068
A10: 11 | B10: Kritik | C10: Tıbbi doğruluk | D10: Farmakoloji | E10: Genel | F10: "(2) → Pitolisant - Tiprolisant" → "pitolisant (eski adı tiprolisant)"; sayı kaldırıldı | G10: Tiprolisant, pitolisantın (BF2.649) eski adıdır; aynı molekül iki ayrı ilaç gibi sayılıyordu. | H10: 1604747625714
A11: 12 | B11: Kritik | C11: Tıbbi doğruluk | D11: Farmakoloji | E11: Genel | F11: "RA tdv'de kullanılan" kök ifadesi kaldırıldı; endikasyonlar cevaba eklendi: abatasept (RA), belatasept (böbrek nakli) | G11: Belatasept RA'da değil, böbrek naklinde rejeksiyon profilaksisinde onaylıdır; RA'da kullanılan CTLA-4-Ig füzyon proteini abatasepttir. | H11: 1604749989489
A12: 16 | B12: Kritik | C12: Tıbbi doğruluk | D12: Farmakoloji | E12: Genel | F12: "PDE4 inh (IL -23 baskılar) → Apremilast" → "Topikal PDE4 inhibitörü → krisaborol" | G12: Apremilast oral PDE4 inhibitörüdür ve psöriazis, psöriatik artrit ile Behçet hastalığının oral ülserlerinde onaylıdır, atopik dermatitte onayı yoktur; atopik dermatitte kullanılan PDE4 inhibitörü topikal krisaboroldür (Katzung). Satır psöriazis kartından aktarılmış görünüyor. | H12: 1604757853167
A13: 20 | B13: Kritik | C13: Tıbbi doğruluk | D13: Farmakoloji | E13: Genel | F13: Katepsin B → katepsin K | G13: Odanakatib, osteoklastların tip I kollajeni yıkmak için salgıladığı katepsin K'nın seçici inhibitörüdür; katepsin B inhibitörü değildir. | H13: 1617568171792
... A1767: 177 | B1767: Yüksek | C1767: Yapısal | D1767: Farmakoloji | E1767: Otakoidler ve Antiinflamatuar İlaçlar | F1767: Otakoid tablosundaki aynı tam yanıtların karşılıklı sızması kapatıldı; özgün numaralar korundu. | G1767: Kaynak: | H1767: 1604749354875

Sheet Kısaltma Sözlüğü
A1: Kısaltma sözlüğü
A2: Kartlardaki kişisel kısaltmalar açıldı; herkesçe bilinen standart tıbbi kısaltmalar korundu. Birden fazla anlamı olan kısaltmalar kartın bağlamına göre açıldı.
A4: Açılan kısaltmalar
A5: Kısaltma | B5: Açılımı (bağlama göre)
A6: Send | B6: sendrom(u)
A7: Hc, Hc'li | B7: hücre, hücreli
A8: Hast | B8: hastalık / hastalığı / hasta
A9: Tdv, Tx | B9: tedavi (“PostTx purpura” = posttransfüzyon purpurası)
A10: Dx, Sx, Bx | B10: tanı, semptom, biyopsi (obstetride “Sx açıklık” = serviks açıklığı)
A11: MoA | B11: etki mekanizması
A12: Res | B12: reseptör / rezistans (direnç)
A13: Eks | B13: eksikliği
A14: İnh | B14: inhibitör / inhibisyon / inhibe eder
A15: Akt | B15: aktivasyon / aktive eder / aktivite
A16: KC, AC, Kİ | B16: karaciğer, akciğer, kemik iliği (sinyal yolaklarında AC = adenilat siklaz)
... A52: Feo, Toxo, AdenoV, RhinoV, Hemagg | B52: feokromositoma, toksoplazma, adenovirüs, rinovirüs, hemaglütinin
A54: Korunan standart kısaltmalar
A55: Alan | B55: Kısaltmalar
A56: Moleküler biyoloji | B56: DNA, RNA (mRNA, tRNA, rRNA), ATP, ADP, AMP, GTP, cAMP, cGMP, NAD(H), NADP(H), FAD(H2), CoA (asetil-CoA, HMG-CoA), PCR, ELISA, HLA, MHC, CD belirteçleri, IL-n, TNF-α, IFN-γ, TGF-β, VEGF, PDGF, EGF(R), G proteinleri (Gs, Gi, Gq), gen ve protein sembolleri
A57: Kimyasal semboller | B57: Na, K, Ca²⁺, Mg, Cl, Fe, Cu, Zn, Li, O2, CO2, HCO3, NH3, NO, pH
A58: Hormonlar | B58: TSH, T3, T4, TRH, FSH, LH, GnRH, GH, IGF-1, ACTH, CRH, PRL, ADH, PTH, hCG, DHEA, ANP, BNP, VIP, CGRP, EPO
A59: Laboratuvar | B59: Hb, Hct, MCV, INR, PT, aPTT, CRP, LDH, ALT, AST, ALP, GGT, CK, BUN, GFR, HbA1c, LDL, HDL, AFP, CEA, CA-125, PSA, ANA, ANCA, ASO, VDRL, RPR, FTA-ABS
A60: Görüntüleme ve testler | B60: EKG, EEG, EMG, EKO, TTE, TEE, BT, MR, USG, PET, ERCP, FAST, DPL
A61: Enfeksiyonlar | B61: HIV, HBV, HCV, HAV, HPV, HSV, VZV, CMV, EBV, RSV, HHV-8, HTLV-1, MRSA, VRE, ESBL
A62: Klinik | B62: DM, HT, KAH, KY, KBY, KOAH, ARDS, Mİ, STEMI, NSTEMI, AF, VF, VT, WPW, ASD, VSD, PDA, SLE, RA, FMF, ALS, SMA, AML, ALL, KML, KLL, MDS, İTP, TTP, HÜS, DİK, SIADH, DKA, İYE, ÜSYE, SSS, GİS, KVS, BOS, KİBAS, SVO, MEN, NF1, PKU, GIST, HCC
